Traceback (most recent call last):
  File "/u/home/wyo/.conda/envs/digital_twin/lib/python3.8/site-packages/pandas/core/indexes/base.py", line 3803, in get_loc
    return self._engine.get_loc(casted_key)
  File "pandas/_libs/index.pyx", line 138, in pandas._libs.index.IndexEngine.get_loc
  File "pandas/_libs/index.pyx", line 165, in pandas._libs.index.IndexEngine.get_loc
  File "pandas/_libs/hashtable_class_helper.pxi", line 5745, in pandas._libs.hashtable.PyObjectHashTable.get_item
  File "pandas/_libs/hashtable_class_helper.pxi", line 5753, in pandas._libs.hashtable.PyObjectHashTable.get_item
KeyError: 'organ'

The above exception was the direct cause of the following exception:

Traceback (most recent call last):
  File "random_forest.py", line 155, in <module>
    cur_patient_label = cur_patient_features[args.label].item()
  File "/u/home/wyo/.conda/envs/digital_twin/lib/python3.8/site-packages/pandas/core/frame.py", line 3805, in __getitem__
    indexer = self.columns.get_loc(key)
  File "/u/home/wyo/.conda/envs/digital_twin/lib/python3.8/site-packages/pandas/core/indexes/base.py", line 3805, in get_loc
    raise KeyError(key) from err
KeyError: 'organ'
